



#include <iostream>


// int main ()
// {
// 	try
// 	{
// 		{
// 			throw 20;
// 		}
// 	}
// 	catch(int e)
// 	{
// 		std::cout << "An exception occurred with value: " << e << std::endl;
// 	}
	
// }



// int main ()
// {
// 	try
// 	{
// 		throw 'U';
// 	}
// 	catch (int H)
// 	{
// 		std::cout << "An integer exception occurred with value: " << H << std::endl;
// 	}
// 	// catch (char H)
// 	// {
// 	// 	std::cout << "A character exception occurred with value: " << H << std::endl;
// 	// }
// }


// int main ()
// {
// 	try 
// 	{
// 		throw "hassan";
// 	}
// 	catch (const char *str)
// 	{
// 		std::cout << "Catching : " << str << std::endl;
// 	}
// }





// int main ()
// {
// 	try 
// 	{
// 		someFunction();
// 	}
// 	catch (const std::logic_error & )
// }




// int main() {
//     try {
//         throw std::runtime_error("Something went wrong!"); // throw a standard runtime error
//     } catch (const std::runtime_error& e) {
//         std::cout << "Caught runtime error: " << e.what() << std::endl;
//     }
//     return 0;
// }


// int main ()
// {
// 	try 
// 	{
// 		throw std::runtime_error("Sothing went wrong!");
// 	}
// 	catch (const std::runtime_error & e)
// 	{
// 		std::cout << "Caught runtime error ; " << e.what() << std::endl;
// 	}
// 	return 0;
// }




// void someFunction()
// {
// 	throw std::logic_error ("An error occurred in someFunction!");
// }

// int main ()
// {
// 	try 
// 	{
// 		someFunction();
// 	}
// 	catch (const std::logic_error & e)
// 	{
// 		std::cout << "Caught logic error : " << e.what() << std::endl;
// 	}
// }



